Workbook
Name TopicList: 'QB Masters'!$P$3:$P$24

Sheet QB Masters
A1: SCORE INDICATORS | F1: COMPETENCY SKILL LEVELS | J1: SUBJECT MASTER | M1: TOPIC MASTER
A3: Score Criteria Name: * | B3: Set Score Range | C3: Set Score Range | D3: Score Indicator Description: | F3: Competency Skill Level Name: * | G3: Competency Skill Level Description: | H3: Enter Competency Check Level Weightage* | J3: Subject Name: * | K3: Subject Description: | M3: Subject Name: * | N3: Topic Name: * | O3: Topic Description: | P3: Topic List Name
A4: 50 Chrs | B4: From | C4: To | F4: 30 Chrs | H4: Values Between 0.01 - 10 | J4: 100 Chrs | M4: 100 Chrs
A5: Excellent | B5: 81 | C5: 100 | F5: Easy | H5: 0.5 | J5: Maths | M5: Maths | N5: Decimals | P5: =+M5&" - "&N5 -> Maths - Decimals
A6: Good | B6: 61 | C6: 80 | F6: Medium | H6: 1.5 | J6: Science | M6: Maths | N6: Measurement | P6: =+M6&" - "&N6 -> Maths - Measurement
A7: Need More Improvement | B7: 41 | C7: 60 | F7: Hard | H7: 2.5 | J7: GK | M7: Maths | N7: Addition/ Subtraction | P7: =+M7&" - "&N7 -> Maths - Addition/ Subtraction
A8: Disappointing | B8: 0 | C8: 40 | J8: Sports | M8: Maths | N8: Time | P8: =+M8&" - "&N8 -> Maths - Time
M9: Maths | N9: Arithmetic | P9: =+M9&" - "&N9 -> Maths - Arithmetic
M10: Maths | N10: Numbers | P10: =+M10&" - "&N10 -> Maths - Numbers
M11: Science | N11: Plants | P11: =+M11&" - "&N11 -> Science - Plants
M12: Science | N12: Animals | P12: =+M12&" - "&N12 -> Science - Animals
M13: Science | N13: Food | P13: =+M13&" - "&N13 -> Science - Food
M14: Science | N14: Our Universe | P14: =+M14&" - "&N14 -> Science - Our Universe
M15: Science | N15: Our Body | P15: =+M15&" - "&N15 -> Science - Our Body
M16: GK | N16: Countries and Capitals | P16: =+M16&" - "&N16 -> GK - Countries and Capitals
M17: GK | N17: India | P17: =+M17&" - "&N17 -> GK - India
M18: GK | N18: Asia | P18: =+M18&" - "&N18 -> GK - Asia
M19: GK | N19: Inventions | P19: =+M19&" - "&N19 -> GK - Inventions
M20: GK | N20: Oceans, Seas, Rivers | P20: =+M20&" - "&N20 -> GK - Oceans, Seas, Rivers
... M24: Sports | N24: Athletics | P24: =+M24&" - "&N24 -> Sports - Athletics

Sheet QB Library (User 1)
B1: QUESTION BANK LIBRARY | D1: Created By User having User Role - Risk Assessor
B2: DEFINE Question Framework | Q2: SET Question Scoring PARAMETERS | U2: Question ATTRIBUTES
A3: # | B3: Map Question to Subject - Topic* | C3: Question Description * | D3: Mention Objective/ Relevance in Assessment | E3: Select Expected Response Type - Multiple Choice Selection* (Min 2) | O3: Correct Answer* | P3: Question Hint | Q3: Set Score Weightage* | R3: Select Competency Check Level* | S3: Show Competency Check Level Weightage* | T3: Estimated Time to Answer this Question* | U3: Allow Random Selection by Assessor* | V3: Allow Random Setting in Assessment* | W3: Question Created By | X3: Question shared with
B4: Select from List | C4: 1500 Chrs | D4: 1500 Chrs | E4: 1* | F4: 2* | G4: 3 | H4: 4 | I4: 5 | J4: 6 | K4: 7 | L4: 8 | M4: 9 | N4: 10 | P4: 1500 Chrs | Q4: Values Between 1 - 10 | R4: Select from List | S4: Values Between 0.01 - 10 | T4: Values Between 1 - 10 | U4: Select from List | V4: Select from List | W4: Mention Name | X4: Mention Name(s)
A5: 1 | B5: Maths - Decimals | C5: What is the decimal point of 5 in 5.05 number? Select your answer from the below list | E5: 1 | F5: 2 | O5: 2 | P5: Count numbers from right to left | Q5: 1 | R5: Easy | S5: 0.5 | T5: 1 | U5: Yes | V5: Yes | W5: User 1
A6: 3 | B6: Maths - Measurement | C6: The length and breadth of a rectangle are respectively 5 and 2. Find area? | D6: Revising formulae | E6: 10 | F6: 20 | G6: 5 | H6: 6 | O6: 1 | P6: Area = l*b | Q6: 3 | R6: Medium | S6: 1.5 | T6: 2 | U6: Yes | V6: No | W6: User 1
A7: 5 | B7: Maths - Addition/ Subtraction | C7: What will be the result if 256 is added to 200? | D7: Simple addition | E7: 356 | F7: 466 | G7: 456 | O7: 3 | Q7: 3 | R7: Easy | S7: 0.5 | T7: 1 | U7: Yes | V7: No | W7: User 1
A8: 8 | B8: Maths - Time | C8: Convert 1 hour and 15 minutes into minutes | E8: 75 | F8: 65 | G8: 115 | O8: 1 | P8: 1 hour is 60 minutes | Q8: 4 | R8: Medium | S8: 1.5 | T8: 6 | U8: No | V8: Yes | W8: User 1
A9: 10 | B9: Maths - Arithmetic | C9: What will be the result if 125 is Divided by 5? | E9: 20 | F9: 10 | G9: 25 | H9: 30 | O9: 3 | Q9: 2 | R9: Medium | S9: 1.5 | T9: 7 | U9: No | V9: No | W9: User 1 | X9: User 3
A10: 14 | B10: Science - Plants | C10: Which of the following is a carnivorous plant? | E10: Venus Flytrap | F10: Aloe Vera | G10: Golden Palm | O10: 1 | Q10: 2 | R10: Medium | S10: 1.5 | T10: 2 | U10: No | V10: No | W10: User 1
A11: 15 | B11: Science - Plants | C11: Where do plants get Carbon Dioxide from? | E11: Air | F11: Soil | G11: Water | O11: 1 | Q11: 3 | R11: Easy | S11: 0.5 | T11: 3 | U11: Yes | V11: No | W11: User 1
A12: 20 | B12: Science - Our Universe | C12: How many planets are there in the Solar System? | E12: 8 | F12: 9 | G12: 10 | H12: 7 | O12: 1 | Q12: 6 | R12: Medium | S12: 1.5 | T12: 1 | U12: Yes | V12: Yes | W12: User 1
A13: 21 | B13: Science - Our Universe | C13: Which is the hottest planet? | E13: Venus | F13: Mars | G13: Mercury | H13: Neptune | I13: Uranus | O13: 1 | Q13: 5 | R13: Medium | S13: 1.5 | T13: 2 | U13: Yes | V13: Yes | W13: User 1
A14: 26 | B14: GK - Countries and Capitals | C14: Whati is the capital of Pakistan? | E14: Islamabad | F14: Karachi | O14: 1 | Q14: 1 | R14: Medium | S14: 1.5 | T14: 2 | U14: No | V14: Yes | W14: User 1
A15: 27 | B15: GK - Countries and Capitals | C15: What is the capital of India? | E15: Agra | F15: Calcutta | G15: Mumbai | H15: Delhi | I15: Amritsar | O15: 4 | Q15: 2 | R15: Easy | S15: 0.5 | T15: 1 | U15: Yes | V15: Yes | W15: User 1
A16: 29 | B16: GK - Countries and Capitals | C16: What is the capital of Brazil? | E16: Rio de Janeiro | F16: Brasilia | O16: 2 | Q16: 5 | R16: Medium | S16: 1.5 | T16: 5 | U16: Yes | V16: No | W16: User 1
A17: 33 | B17: GK - Asia | C17: Which is the largest country in Asia? | E17: India | F17: China | G17: Pakistan | O17: 2 | Q17: 6 | R17: Medium | S17: 1.5 | T17: 4 | U17: Yes | V17: Yes | W17: User 1
A18: 39 | B18: Sports - Olympics | C18: Who is the first female U.S. gymnast to win four gold medals at a single Games? | E18: Shawn Johnson | F18: Gabby Douglas | G18: Simone Biles | O18: 3 | Q18: 4 | R18: Medium | S18: 1.5 | T18: 7 | U18: Yes | V18: No | W18: User 1
A19: 43 | B19: Sports - Cricket | C19: Three of Australia’s Test cricket captains were nicknamed Pugsley, Tubby, and Punter. | E19: TRUE | F19: FALSE | O19: 1 | Q19: 3 | R19: Hard | S19: 2.5 | T19: 3 | U19: Yes | V19: No | W19: User 1
A20: 48 | B20: Sports - Athletics | C20: Which American athlete won four gold medals at the 1936 Olympic Games in Berlin? | E20: Jim Brown | F20: Edwin Moses | G20: Joe Louis | H20: Jesse Owens | O20: 4 | Q20: 8 | R20: Hard | S20: 2.5 | T20: 5 | U20: No | V20: No | W20: User 1

Sheet QB Library (User 2)
B1: QUESTION BANK LIBRARY | D1: Created By User having User Role - Risk Assessor
B2: DEFINE Question Framework | Q2: SET Question Scoring PARAMETERS | U2: Question ATTRIBUTES
A3: # | B3: Map Question to Subject - Topic* | C3: Question Description * | D3: Mention Objective/ Relevance in Assessment | E3: Select Expected Response Type - Multiple Choice Selection* (Min 2) | O3: Correct Answer* | P3: Question Hint | Q3: Set Score Weightage* | R3: Select Competency Check Level* | S3: Show Competency Check Level Weightage* | T3: Estimated Time to Answer this Question* | U3: Allow Random Selection by Assessor* | V3: Allow Random Setting in Assessment* | W3: Question Created By | X3: Question shared with
B4: Select from List | C4: 1500 Chrs | D4: 1500 Chrs | E4: 1* | F4: 2* | G4: 3 | H4: 4 | I4: 5 | J4: 6 | K4: 7 | L4: 8 | M4: 9 | N4: 10 | P4: 1500 Chrs | Q4: Values Between 1 - 10 | R4: Select from List | S4: Values Between 0.01 - 10 | T4: Values Between 1 - 10 | U4: Select from List | V4: Select from List | W4: Mention Name | X4: Mention Name(s)
A5: 2 | B5: Maths - Decimals | C5: How many decimal points remain when 5.236 is multiplied with 100 | E5: 0 | F5: 1 | G5: 2 | H5: 3 | O5: 2 | P5: Multiply by 100 and check number of digits after decimal point | Q5: 2 | R5: Medium | S5: 1.5 | T5: 1 mins | U5: No | V5: Yes | W5: User 2 | X5: User 1
A6: 7 | B6: Maths - Addition/ Subtraction | C6: What will be the result if 35 is Subtract from 63? | E6: 13 | F6: 25 | G6: 28 | H6: -28 | O6: 3 | Q6: 3 | R6: Hard | S6: 2.5 | T6: 5 | U6: No | V6: Yes | W6: User 2 | X6: User 3
A7: 12 | B7: Maths - Numbers | C7: LCM of 2 numbers is 25. HCF of the two numbers is 3. What is their product? | E7: 70 | F7: 25 | G7: 50 | H7: 75 | O7: 4 | P7: Product of two numbers is equal to product of their LCM and HCF. | Q7: 1 | R7: Medium | S7: 1.5 | T7: 3 | U7: No | V7: Yes | W7: User 2 | X7: User 3
A8: 17 | B8: Science - Animals | C8: Which of the following is a domestic animal? | E8: Lion | F8: Wolf | G8: Tiger | H8: Cow | O8: 4 | Q8: 1 | R8: Medium | S8: 1.5 | T8: 5 | U8: No | V8: Yes | W8: User 2
A9: 23 | B9: Science - Our Body | C9: What part of the body has no blood supply? | E9: Cornea | F9: Hands | G9: Feet | H9: Ear | O9: 1 | Q9: 6 | R9: Hard | S9: 2.5 | T9: 6 | U9: No | V9: No | W9: User 2
A10: 25 | B10: Science - Our Body | C10: How many bones are there approximately in the human body? | E10: 216 | F10: 50 | G10: 500 | H10: 1000 | O10: 1 | Q10: 2 | R10: Easy | S10: 0.5 | T10: 8 | U10: Yes | V10: No | W10: User 2
A11: 31 | B11: GK - India | C11: When is Independence Day celebrated in India? | E11: 45519 | F11: 45317 | G11: 45567 | O11: 1 | Q11: 5 | R11: Hard | S11: 2.5 | T11: 5 | U11: Yes | V11: Yes | W11: User 2
A12: 32 | B12: GK - India | C12: What colour is not in the Indian flag? | E12: White | F12: Saffron | G12: Black | H12: Green | I12: Blue | O12: 3 | Q12: 3 | R12: Medium | S12: 1.5 | T12: 6 | U12: No | V12: No | W12: User 2
A13: 36 | B13: GK - Oceans, Seas, Rivers | C13: Which is the longest river? | E13: Brahmputra | F13: Nile | G13: Ganga | H13: Yamuna | O13: 2 | Q13: 5 | R13: Hard | S13: 2.5 | T13: 6 | U13: No | V13: Yes | W13: User 2
A14: 41 | B14: Sports - National Games | C14: When were the first Modern National Games on the lines of the Olympics held? | E14: 1986 | F14: 1985 | G14: 1987 | H14: 1984 | O14: 2 | Q14: 5 | R14: Medium | S14: 1.5 | T14: 2 | U14: Yes | V14: No | W14: User 2
A15: 42 | B15: Sports - National Games | C15: Which is India's national game? | E15: Hockey | F15: Cricket | G15: Football | O15: 1 | Q15: 2 | R15: Hard | S15: 2.5 | T15: 5 | U15: No | V15: No | W15: User 2
A16: 44 | B16: Sports - Cricket | C16: For how many days is a Test match scheduled? | E16: 5 days | F16: 1 day | G16: 1 week | O16: 1 | Q16: 5 | R16: Easy | S16: 0.5 | T16: 4 | U16: No | V16: No | W16: User 2
A17: 45 | B17: Sports - Cricket | C17: In which year were the first laws of cricket believed to have been written? | E17: 1882 | F17: 1709 | G17: 1774 | O17: 3 | Q17: 5 | R17: Medium | S17: 1.5 | T17: 7 | U17: Yes | V17: Yes | W17: User 2
A18: 46 | B18: Sports - Cricket | C18: Cricket umpires use a large variety of signals to make sure that the correct scores are kept. What does it mean if an umpire raises both arms straight above his head? | E18: Out | F18: Wide ball | G18: 6 runs | H18: 4 runs | O18: 3 | Q18: 6 | R18: Medium | S18: 1.5 | T18: 8 | U18: Yes | V18: Yes | W18: User 2
A19: 47 | B19: Sports - Cricket | C19: Lord’s, the most famous of all English cricket grounds, got its name because of the popularity of the game with the English aristocracy. | E19: TRUE | F19: FALSE | O19: 2 | Q19: 9 | R19: Hard | S19: 2.5 | T19: 9 | U19: No | V19: Yes | W19: User 2
A20: 49 | B20: Sports - Athletics | C20: Who was the first pole-vaulter to clear 20 feet (6.1 metres)? | E20: Bob Richards | F20: Don Bragg | G20: Sergey Bubka | O20: 3 | Q20: 7 | R20: Hard | S20: 2.5 | T20: 4 | U20: Yes | V20: No | W20: User 2
A21: 50 | B21: Sports - Athletics | C21: Usain Bolt is the only man ever to win the 100 meters, 200 meters, and 4 x 100-meter relay in a single Olympics. | E21: TRUE | F21: FALSE | O21: 2 | Q21: 1 | R21: Easy | S21: 0.5 | T21: 2 | U21: Yes | V21: No | W21: User 2

Sheet QB Library (User 3)
B1: QUESTION BANK LIBRARY | D1: Created By User having User Role - Risk Assessor
B2: DEFINE Question Framework | Q2: SET Question Scoring PARAMETERS | U2: Question ATTRIBUTES
A3: # | B3: Map Question to Subject - Topic* | C3: Question Description * | D3: Mention Objective/ Relevance in Assessment | E3: Select Expected Response Type - Multiple Choice Selection* (Min 2) | O3: Correct Answer* | P3: Question Hint | Q3: Set Score Weightage* | R3: Select Competency Check Level* | S3: Show Competency Check Level Weightage* | T3: Estimated Time to Answer this Question* | U3: Allow Random Selection by Assessor* | V3: Allow Random Setting in Assessment* | W3: Question Created By | X3: Question shared with
B4: Select from List | C4: 1500 Chrs | D4: 1500 Chrs | E4: 1* | F4: 2* | G4: 3 | H4: 4 | I4: 5 | J4: 6 | K4: 7 | L4: 8 | M4: 9 | N4: 10 | P4: 1500 Chrs | Q4: Values Between 1 - 10 | R4: Select from List | S4: Values Between 0.01 - 10 | T4: Values Between 1 - 10 | U4: Select from List | V4: Select from List | W4: Mention Name | X4: Mention Name(s)
A5: 4 | B5: Maths - Measurement | C5: Radius of circle is 5cm. Find area in cm²? | D5: Revising formulae | E5: 25π | F5: 5π | G5: 10π | H5: 25 | I5: 25π | O5: 5 | P5: Area=πr² | Q5: 2 | R5: Hard | S5: 2.5 | T5: 2 | U5: Yes | V5: No | W5: User 3
A6: 6 | B6: Maths - Addition/ Subtraction | C6: Raju has 10 cookies and Aman has 25. They give their cookies to Aryan. How many cookies does Aryan have now? | D6: Word problems | E6: 35 | F6: 30 | O6: 1 | P6: Assume variables and add | Q6: 2 | R6: Medium | S6: 1.5 | T6: 3 | U6: No | V6: Yes | W6: User 3 | X6: User 1
A7: 9 | B7: Maths - Time | C7: How many seconds are in 1 hour? | E7: 3000 | F7: 3600 | O7: 2 | Q7: 2 | R7: Medium | S7: 1.5 | T7: 8 | U7: Yes | V7: No | W7: User 3 | X7: User 1
A8: 11 | B8: Maths - Arithmetic | C8: Divide 1000 into 8 parts. What is the size of each group now? | D8: Word problems | E8: 125 | F8: 225 | O8: 1 | Q8: 3 | R8: Hard | S8: 2.5 | T8: 2 | U8: Yes | V8: No | W8: User 3
A9: 13 | B9: Maths - Numbers | C9: What is the exponent of 2 in the prime factorization of 24 | E9: 3 | F9: 2 | G9: 4 | H9: 1 | I9: 2 | O9: 1 | Q9: 6 | R9: Medium | S9: 1.5 | T9: 5 | U9: Yes | V9: Yes | W9: User 3
A10: 16 | B10: Science - Animals | C10: Which of the following is a wild animal? | E10: Rabbit | F10: Horse | G10: Lion | H10: Cow | O10: 3 | Q10: 5 | R10: Hard | S10: 2.5 | T10: 6 | U10: No | V10: Yes | W10: User 3
A11: 18 | B11: Science - Food | C11: Which of these is not a type of bell pepper? | E11: Yellow | F11: Red | G11: Purple | H11: Green | O11: 3 | Q11: 2 | R11: Easy | S11: 0.5 | T11: 7 | U11: No | V11: No | W11: User 3
A12: 19 | B12: Science - Food | C12: Potatoes contain a major part of what? | E12: Carbohydrates | F12: Proteins | O12: 1 | Q12: 3 | R12: Hard | S12: 2.5 | T12: 8 | U12: Yes | V12: No | W12: User 3
A13: 22 | B13: Science - Our Universe | C13: Which galaxy are we in? | E13: Canis Major Dwarf | F13: Milky Way | G13: Draco 2 | H13: Andromeda | O13: 2 | Q13: 9 | R13: Hard | S13: 2.5 | T13: 5 | U13: Yes | V13: No | W13: User 3
A14: 24 | B14: Science - Our Body | C14: We inhale air through what part? | E14: Hands | F14: Nose | G14: Ear | H14: Eyes | O14: 2 | Q14: 6 | R14: Medium | S14: 1.5 | T14: 9 | U14: No | V14: No | W14: User 3
A15: 28 | B15: GK - Countries and Capitals | C15: What is the capital of China? | E15: Beijing | F15: Shanghai | G15: Guangzhou | O15: 1 | Q15: 3 | R15: Hard | S15: 2.5 | T15: 4 | U15: No | V15: No | W15: User 3
A16: 30 | B16: GK - India | C16: Who was the first prime minister of India? | E16: Jawaharlal Nehru | F16: Rajendra Prasad | G16: B. R. Ambedkar | O16: 1 | Q16: 8 | R16: Hard | S16: 2.5 | T16: 6 | U16: No | V16: Yes | W16: User 3
A17: 34 | B17: GK - Asia | C17: Which of these countries does not border India? | E17: Pakistan | F17: China | G17: Nepal | H17: Russia | O17: 4 | Q17: 4 | R17: Easy | S17: 0.5 | T17: 8 | U17: No | V17: No | W17: User 3
A18: 35 | B18: GK - Inventions | C18: Who invented the Steam Engine? | E18: Thomas Alva Edison | F18: James Watt | G18: Albert Einstein | O18: 2 | Q18: 4 | R18: Easy | S18: 0.5 | T18: 2 | U18: Yes | V18: Yes | W18: User 3
A19: 37 | B19: GK - Oceans, Seas, Rivers | C19: Which rivers originate from Himalayas? | E19: Indus | F19: Ganga | G19: All of the Above | O19: 3 | Q19: 6 | R19: Medium | S19: 1.5 | T19: 9 | U19: Yes | V19: Yes | W19: User 3
A20: 38 | B20: Sports - Olympics | C20: Which of the following is not an Olympic sport? | E20: Skateboarding | F20: High jumping | G20: Swimming | H20: Wrestling | O20: 1 | Q20: 5 | R20: Easy | S20: 0.5 | T20: 5 | U20: No | V20: No | W20: User 3
A21: 40 | B21: Sports - National Games | C21: In which year, the first National Games of India was held? | E21: 1924 | F21: 1922 | G21: 1926 | H21: 1930 | O21: 1 | Q21: 7 | R21: Hard | S21: 2.5 | T21: 1 | U21: No | V21: No | W21: User 3

Sheet QB Reserve
B1: QUESTION BANK RESERVE | D1: Created By User having User Role - Risk Assessor
B2: DEFINE Question Framework | Q2: SET Question Scoring PARAMETERS | U2: Question ATTRIBUTES
A3: # | B3: Map Question to Subject - Topic* | C3: Question Description * | D3: Mention Objective/ Relevance in Assessment | E3: Select Expected Response Type - Multiple Choice Selection* (Min 2) | O3: Correct Answer* | P3: Question Hint | Q3: Set Score Weightage* | R3: Select Competency Check Level* | S3: Show Competency Check Level Weightage* | T3: Estimated Time to Answer this Question* | U3: Allow Random Selection by Assessor* | V3: Allow Random Setting in Assessment* | W3: Question Created By
B4: Select from List | C4: 1500 Chrs | D4: 1500 Chrs | E4: 1* | F4: 2* | G4: 3 | H4: 4 | I4: 5 | J4: 6 | K4: 7 | L4: 8 | M4: 9 | N4: 10 | P4: 1500 Chrs | Q4: Values Between 1 - 10 | R4: Select from List | S4: Values Between 0.01 - 10 | T4: Values Between 1 - 10 | U4: Select from List | V4: Select from List | W4: Mention Name
A5: =+IF(C5<>"",1,"-") -> 1 | B5: Maths - Decimals | C5: What is the decimal point of 5 in 5.05 number? Select your answer from the below list | E5: 1 | F5: 2 | O5: 2 | P5: Count numbers from right to left | Q5: 1 | R5: Easy | S5: =+VLOOKUP(R5,'QB Masters'!F:H,3,0) -> 0.5 | T5: 1 | U5: Yes | V5: Yes | W5: User 1
A6: =+IF(C6<>"",A5+1,"-") -> 2 | B6: Maths - Decimals | C6: How many decimal points remain when 5.236 is multiplied with 100 | E6: 0 | F6: 1 | G6: 2 | H6: 3 | O6: 2 | P6: Multiply by 100 and check number of digits after decimal point | Q6: 2 | R6: Medium | S6: =+VLOOKUP(R6,'QB Masters'!F:H,3,0) -> 1.5 | T6: 1 mins | U6: No | V6: Yes | W6: User 2
A7: =+IF(C7<>"",A6+1,"-") -> 3 | B7: Maths - Measurement | C7: The length and breadth of a rectangle are respectively 5 and 2. Find area? | D7: Revising formulae | E7: 10 | F7: 20 | G7: 5 | H7: 6 | O7: 1 | P7: Area = l*b | Q7: 3 | R7: Medium | S7: =+VLOOKUP(R7,'QB Masters'!F:H,3,0) -> 1.5 | T7: 2 | U7: Yes | V7: No | W7: User 1
A8: =+IF(C8<>"",A7+1,"-") -> 4 | B8: Maths - Measurement | C8: Radius of circle is 5cm. Find area in cm²? | D8: Revising formulae | E8: 25π | F8: 5π | G8: 10π | H8: 25 | I8: 25π | O8: 5 | P8: Area=πr² | Q8: 2 | R8: Hard | S8: =+VLOOKUP(R8,'QB Masters'!F:H,3,0) -> 2.5 | T8: 2 | U8: Yes | V8: No | W8: User 3
A9: =+IF(C9<>"",A8+1,"-") -> 5 | B9: Maths - Addition/ Subtraction | C9: What will be the result if 256 is added to 200? | D9: Simple addition | E9: 356 | F9: 466 | G9: 456 | O9: 3 | Q9: 3 | R9: Easy | S9: =+VLOOKUP(R9,'QB Masters'!F:H,3,0) -> 0.5 | T9: 1 | U9: Yes | V9: No | W9: User 1
A10: =+IF(C10<>"",A9+1,"-") -> 6 | B10: Maths - Addition/ Subtraction | C10: Raju has 10 cookies and Aman has 25. They give their cookies to Aryan. How many cookies does Aryan have now? | D10: Word problems | E10: 35 | F10: 30 | O10: 1 | P10: Assume variables and add | Q10: 2 | R10: Medium | S10: =+VLOOKUP(R10,'QB Masters'!F:H,3,0) -> 1.5 | T10: 3 | U10: No | V10: Yes | W10: User 3
A11: =+IF(C11<>"",A10+1,"-") -> 7 | B11: Maths - Addition/ Subtraction | C11: What will be the result if 35 is Subtract from 63? | E11: 13 | F11: 25 | G11: 28 | H11: -28 | O11: 3 | Q11: 3 | R11: Hard | S11: =+VLOOKUP(R11,'QB Masters'!F:H,3,0) -> 2.5 | T11: 5 | U11: No | V11: Yes | W11: User 2
A12: =+IF(C12<>"",A11+1,"-") -> 8 | B12: Maths - Time | C12: Convert 1 hour and 15 minutes into minutes | E12: 75 | F12: 65 | G12: 115 | O12: 1 | P12: 1 hour is 60 minutes | Q12: 4 | R12: Medium | S12: =+VLOOKUP(R12,'QB Masters'!F:H,3,0) -> 1.5 | T12: 6 | U12: No | V12: Yes | W12: User 1
A13: =+IF(C13<>"",A12+1,"-") -> 9 | B13: Maths - Time | C13: How many seconds are in 1 hour? | E13: 3000 | F13: 3600 | O13: 2 | Q13: 2 | R13: Medium | S13: =+VLOOKUP(R13,'QB Masters'!F:H,3,0) -> 1.5 | T13: 8 | U13: Yes | V13: No | W13: User 3
A14: =+IF(C14<>"",A13+1,"-") -> 10 | B14: Maths - Arithmetic | C14: What will be the result if 125 is Divided by 5? | E14: 20 | F14: 10 | G14: 25 | H14: 30 | O14: 3 | Q14: 2 | R14: Medium | S14: =+VLOOKUP(R14,'QB Masters'!F:H,3,0) -> 1.5 | T14: 7 | U14: No | V14: No | W14: User 1
A15: =+IF(C15<>"",A14+1,"-") -> 11 | B15: Maths - Arithmetic | C15: Divide 1000 into 8 parts. What is the size of each group now? | D15: Word problems | E15: 125 | F15: 225 | O15: 1 | Q15: 3 | R15: Hard | S15: =+VLOOKUP(R15,'QB Masters'!F:H,3,0) -> 2.5 | T15: 2 | U15: Yes | V15: No | W15: User 3
A16: =+IF(C16<>"",A15+1,"-") -> 12 | B16: Maths - Numbers | C16: LCM of 2 numbers is 25. HCF of the two numbers is 3. What is their product? | E16: 70 | F16: 25 | G16: 50 | H16: 75 | O16: 4 | P16: Product of two numbers is equal to product of their LCM and HCF. | Q16: 1 | R16: Medium | S16: =+VLOOKUP(R16,'QB Masters'!F:H,3,0) -> 1.5 | T16: 3 | U16: No | V16: Yes | W16: User 2
A17: =+IF(C17<>"",A16+1,"-") -> 13 | B17: Maths - Numbers | C17: What is the exponent of 2 in the prime factorization of 24 | E17: 3 | F17: 2 | G17: 4 | H17: 1 | I17: 2 | O17: 1 | Q17: 6 | R17: Medium | S17: =+VLOOKUP(R17,'QB Masters'!F:H,3,0) -> 1.5 | T17: 5 | U17: Yes | V17: Yes | W17: User 3
A18: =+IF(C18<>"",A17+1,"-") -> 14 | B18: Science - Plants | C18: Which of the following is a carnivorous plant? | E18: Venus Flytrap | F18: Aloe Vera | G18: Golden Palm | O18: 1 | Q18: 2 | R18: Medium | S18: =+VLOOKUP(R18,'QB Masters'!F:H,3,0) -> 1.5 | T18: 2 | U18: No | V18: No | W18: User 1
A19: =+IF(C19<>"",A18+1,"-") -> 15 | B19: Science - Plants | C19: Where do plants get Carbon Dioxide from? | E19: Air | F19: Soil | G19: Water | O19: 1 | Q19: 3 | R19: Easy | S19: =+VLOOKUP(R19,'QB Masters'!F:H,3,0) -> 0.5 | T19: 3 | U19: Yes | V19: No | W19: User 1
A20: =+IF(C20<>"",A19+1,"-") -> 16 | B20: Science - Animals | C20: Which of the following is a wild animal? | E20: Rabbit | F20: Horse | G20: Lion | H20: Cow | O20: 3 | Q20: 5 | R20: Hard | S20: =+VLOOKUP(R20,'QB Masters'!F:H,3,0) -> 2.5 | T20: 6 | U20: No | V20: Yes | W20: User 3
A21: =+IF(C21<>"",A20+1,"-") -> 17 | B21: Science - Animals | C21: Which of the following is a domestic animal? | E21: Lion | F21: Wolf | G21: Tiger | H21: Cow | O21: 4 | Q21: 1 | R21: Medium | S21: =+VLOOKUP(R21,'QB Masters'!F:H,3,0) -> 1.5 | T21: 5 | U21: No | V21: Yes | W21: User 2
A22: =+IF(C22<>"",A21+1,"-") -> 18 | B22: Science - Food | C22: Which of these is not a type of bell pepper? | E22: Yellow | F22: Red | G22: Purple | H22: Green | O22: 3 | Q22: 2 | R22: Easy | S22: =+VLOOKUP(R22,'QB Masters'!F:H,3,0) -> 0.5 | T22: 7 | U22: No | V22: No | W22: User 3
A23: =+IF(C23<>"",A22+1,"-") -> 19 | B23: Science - Food | C23: Potatoes contain a major part of what? | E23: Carbohydrates | F23: Proteins | O23: 1 | Q23: 3 | R23: Hard | S23: =+VLOOKUP(R23,'QB Masters'!F:H,3,0) -> 2.5 | T23: 8 | U23: Yes | V23: No | W23: User 3
A24: =+IF(C24<>"",A23+1,"-") -> 20 | B24: Science - Our Universe | C24: How many planets are there in the Solar System? | E24: 8 | F24: 9 | G24: 10 | H24: 7 | O24: 1 | Q24: 6 | R24: Medium | S24: =+VLOOKUP(R24,'QB Masters'!F:H,3,0) -> 1.5 | T24: 1 | U24: Yes | V24: Yes | W24: User 1
A25: =+IF(C25<>"",A24+1,"-") -> 21 | B25: Science - Our Universe | C25: Which is the hottest planet? | E25: Venus | F25: Mars | G25: Mercury | H25: Neptune | I25: Uranus | O25: 1 | Q25: 5 | R25: Medium | S25: =+VLOOKUP(R25,'QB Masters'!F:H,3,0) -> 1.5 | T25: 2 | U25: Yes | V25: Yes | W25: User 1
A26: =+IF(C26<>"",A25+1,"-") -> 22 | B26: Science - Our Universe | C26: Which galaxy are we in? | E26: Canis Major Dwarf | F26: Milky Way | G26: Draco 2 | H26: Andromeda | O26: 2 | Q26: 9 | R26: Hard | S26: =+VLOOKUP(R26,'QB Masters'!F:H,3,0) -> 2.5 | T26: 5 | U26: Yes | V26: No | W26: User 3
A27: =+IF(C27<>"",A26+1,"-") -> 23 | B27: Science - Our Body | C27: What part of the body has no blood supply? | E27: Cornea | F27: Hands | G27: Feet | H27: Ear | O27: 1 | Q27: 6 | R27: Hard | S27: =+VLOOKUP(R27,'QB Masters'!F:H,3,0) -> 2.5 | T27: 6 | U27: No | V27: No | W27: User 2
A28: =+IF(C28<>"",A27+1,"-") -> 24 | B28: Science - Our Body | C28: We inhale air through what part? | E28: Hands | F28: Nose | G28: Ear | H28: Eyes | O28: 2 | Q28: 6 | R28: Medium | S28: =+VLOOKUP(R28,'QB Masters'!F:H,3,0) -> 1.5 | T28: 9 | U28: No | V28: No | W28: User 3
A29: =+IF(C29<>"",A28+1,"-") -> 25 | B29: Science - Our Body | C29: How many bones are there approximately in the human body? | E29: 216 | F29: 50 | G29: 500 | H29: 1000 | O29: 1 | Q29: 2 | R29: Easy | S29: =+VLOOKUP(R29,'QB Masters'!F:H,3,0) -> 0.5 | T29: 8 | U29: Yes | V29: No | W29: User 2
A30: =+IF(C30<>"",A29+1,"-") -> 26 | B30: GK - Countries and Capitals | C30: Whati is the capital of Pakistan? | E30: Islamabad | F30: Karachi | O30: 1 | Q30: 1 | R30: Medium | S30: =+VLOOKUP(R30,'QB Masters'!F:H,3,0) -> 1.5 | T30: 2 | U30: No | V30: Yes | W30: User 1
A31: =+IF(C31<>"",A30+1,"-") -> 27 | B31: GK - Countries and Capitals | C31: What is the capital of India? | E31: Agra | F31: Calcutta | G31: Mumbai | H31: Delhi | I31: Amritsar | O31: 4 | Q31: 2 | R31: Easy | S31: =+VLOOKUP(R31,'QB Masters'!F:H,3,0) -> 0.5 | T31: 1 | U31: Yes | V31: Yes | W31: User 1
A32: =+IF(C32<>"",A31+1,"-") -> 28 | B32: GK - Countries and Capitals | C32: What is the capital of China? | E32: Beijing | F32: Shanghai | G32: Guangzhou | O32: 1 | Q32: 3 | R32: Hard | S32: =+VLOOKUP(R32,'QB Masters'!F:H,3,0) -> 2.5 | T32: 4 | U32: No | V32: No | W32: User 3
A33: =+IF(C33<>"",A32+1,"-") -> 29 | B33: GK - Countries and Capitals | C33: What is the capital of Brazil? | E33: Rio de Janeiro | F33: Brasilia | O33: 2 | Q33: 5 | R33: Medium | S33: =+VLOOKUP(R33,'QB Masters'!F:H,3,0) -> 1.5 | T33: 5 | U33: Yes | V33: No | W33: User 1
A34: =+IF(C34<>"",A33+1,"-") -> 30 | B34: GK - India | C34: Who was the first prime minister of India? | E34: Jawaharlal Nehru | F34: Rajendra Prasad | G34: B. R. Ambedkar | O34: 1 | Q34: 8 | R34: Hard | S34: =+VLOOKUP(R34,'QB Masters'!F:H,3,0) -> 2.5 | T34: 6 | U34: No | V34: Yes | W34: User 3
A35: =+IF(C35<>"",A34+1,"-") -> 31 | B35: GK - India | C35: When is Independence Day celebrated in India? | E35: 45519 | F35: 45317 | G35: 45567 | O35: 1 | Q35: 5 | R35: Hard | S35: =+VLOOKUP(R35,'QB Masters'!F:H,3,0) -> 2.5 | T35: 5 | U35: Yes | V35: Yes | W35: User 2
A36: =+IF(C36<>"",A35+1,"-") -> 32 | B36: GK - India | C36: What colour is not in the Indian flag? | E36: White | F36: Saffron | G36: Black | H36: Green | I36: Blue | O36: 3 | Q36: 3 | R36: Medium | S36: =+VLOOKUP(R36,'QB Masters'!F:H,3,0) -> 1.5 | T36: 6 | U36: No | V36: No | W36: User 2
A37: =+IF(C37<>"",A36+1,"-") -> 33 | B37: GK - Asia | C37: Which is the largest country in Asia? | E37: India | F37: China | G37: Pakistan | O37: 2 | Q37: 6 | R37: Medium | S37: =+VLOOKUP(R37,'QB Masters'!F:H,3,0) -> 1.5 | T37: 4 | U37: Yes | V37: Yes | W37: User 1
A38: =+IF(C38<>"",A37+1,"-") -> 34 | B38: GK - Asia | C38: Which of these countries does not border India? | E38: Pakistan | F38: China | G38: Nepal | H38: Russia | O38: 4 | Q38: 4 | R38: Easy | S38: =+VLOOKUP(R38,'QB Masters'!F:H,3,0) -> 0.5 | T38: 8 | U38: No | V38: No | W38: User 3
A39: =+IF(C39<>"",A38+1,"-") -> 35 | B39: GK - Inventions | C39: Who invented the Steam Engine? | E39: Thomas Alva Edison | F39: James Watt | G39: Albert Einstein | O39: 2 | Q39: 4 | R39: Easy | S39: =+VLOOKUP(R39,'QB Masters'!F:H,3,0) -> 0.5 | T39: 2 | U39: Yes | V39: Yes | W39: User 3
A40: =+IF(C40<>"",A39+1,"-") -> 36 | B40: GK - Oceans, Seas, Rivers | C40: Which is the longest river? | E40: Brahmputra | F40: Nile | G40: Ganga | H40: Yamuna | O40: 2 | Q40: 5 | R40: Hard | S40: =+VLOOKUP(R40,'QB Masters'!F:H,3,0) -> 2.5 | T40: 6 | U40: No | V40: Yes | W40: User 2
...

Sheet Subject Assessment (1)
A1: SUBJECT ASSESSMENT: | D1: Mathematics - Level 1 | F1: TOTAL NO. OF QUESTIONS: | H1: =MAX(A:A) -> 7 | J1: TOTAL SCORE WEIGHTAGE: | L1: =SUM(Q:Q) -> 17 | N1: TOTAL TIME AVAILABLE: | P1: =SUM(R:R)+5 -> 26 | S1: User 1 | T1: =+COUNTIF($S$5:$S$32,S1) -> 4
B2: Created By User 1 having User Role - Process Owner | E2: 5 | F2: 6 | G2: 7 | H2: 8 | I2: 9 | J2: 10 | K2: 11 | L2: 12 | M2: 13 | N2: 14 | S2: User 2 | T2: =+COUNTIF($S$5:$S$32,S2) -> 1
A3: Ques No. | B3: Enter QB Reserve No.* | C3: Map Question to Subject - Topic* | D3: Question Description * | E3: Select Expected Response Type - Multiple Choice Selection* (Min 2) | O3: Select Correct Answer* | P3: Question Hint | Q3: Set Score Weightage* | R3: Total Time avaiable | S3: User 3 | T3: =+COUNTIF($S$5:$S$32,S3) -> 2
B4: 1 - 50 | E4: 1* | F4: 2* | G4: 3 | H4: 4 | I4: 5 | J4: 6 | K4: 7 | L4: 8 | M4: 9 | N4: 10
A5: =+IF(LEN(D5)>5,1,"-") -> 1 | B5: 1 | C5: Maths - Airthmetic | D5: =IFERROR(VLOOKUP(B5,'QB Reserve'!A:C,3,0),"-") -> What is the decimal point of 5 in 5.05 number? Select your answer from the below list | E5: =IFERROR(VLOOKUP($B5,'QB Reserve'!$A:$N,E$2,0),"-") -> 1 | F5: =IFERROR(VLOOKUP($B5,'QB Reserve'!$A:$N,F$2,0),"-") -> 2 | G5: =IFERROR(VLOOKUP($B5,'QB Reserve'!$A:$N,G$2,0),"-") -> 0 | H5: =IFERROR(VLOOKUP($B5,'QB Reserve'!$A:$N,H$2,0),"-") -> 0 | I5: =IFERROR(VLOOKUP($B5,'QB Reserve'!$A:$N,I$2,0),"-") -> 0 | J5: =IFERROR(VLOOKUP($B5,'QB Reserve'!$A:$N,J$2,0),"-") -> 0 | K5: =IFERROR(VLOOKUP($B5,'QB Reserve'!$A:$N,K$2,0),"-") -> 0 | L5: =IFERROR(VLOOKUP($B5,'QB Reserve'!$A:$N,L$2,0),"-") -> 0 | ... N5: =IFERROR(VLOOKUP($B5,'QB Reserve'!$A:$N,N$2,0),"-") -> 0 | P5: =IFERROR(VLOOKUP(B5,'QB Reserve'!A:P,16,0),"-") -> Count numbers from right to left | Q5: =IFERROR(VLOOKUP(B5,'QB Reserve'!A:Q,17,0),"-") -> 1 | R5: =IFERROR(VLOOKUP(B5,'QB Reserve'!A:T,20,0),"-") -> 1 | S5: =+VLOOKUP(B5,'QB Reserve'!A:W,23,0) -> User 1
A6: =+IF(LEN(D6)>5,A5+1,"-") -> 2 | B6: 3 | C6: =IFERROR(VLOOKUP(B6,'QB Reserve'!A:B,2,0),"-") -> Maths - Measurement | D6: =IFERROR(VLOOKUP(B6,'QB Reserve'!A:C,3,0),"-") -> The length and breadth of a rectangle are respectively 5 and 2. Find area? | E6: =IFERROR(VLOOKUP($B6,'QB Reserve'!$A:$N,E$2,0),"-") -> 10 | F6: =IFERROR(VLOOKUP($B6,'QB Reserve'!$A:$N,F$2,0),"-") -> 20 | G6: =IFERROR(VLOOKUP($B6,'QB Reserve'!$A:$N,G$2,0),"-") -> 5 | H6: =IFERROR(VLOOKUP($B6,'QB Reserve'!$A:$N,H$2,0),"-") -> 6 | I6: =IFERROR(VLOOKUP($B6,'QB Reserve'!$A:$N,I$2,0),"-") -> 0 | J6: =IFERROR(VLOOKUP($B6,'QB Reserve'!$A:$N,J$2,0),"-") -> 0 | K6: =IFERROR(VLOOKUP($B6,'QB Reserve'!$A:$N,K$2,0),"-") -> 0 | L6: =IFERROR(VLOOKUP($B6,'QB Reserve'!$A:$N,L$2,0),"-") -> 0 | ... N6: =IFERROR(VLOOKUP($B6,'QB Reserve'!$A:$N,N$2,0),"-") -> 0 | P6: =IFERROR(VLOOKUP(B6,'QB Reserve'!A:P,16,0),"-") -> Area = l*b | Q6: =IFERROR(VLOOKUP(B6,'QB Reserve'!A:Q,17,0),"-") -> 3 | R6: =IFERROR(VLOOKUP(B6,'QB Reserve'!A:T,20,0),"-") -> 2 | S6: =+VLOOKUP(B6,'QB Reserve'!A:W,23,0) -> User 1
A7: =+IF(LEN(D7)>5,A6+1,"-") -> 3 | B7: 6 | C7: =IFERROR(VLOOKUP(B7,'QB Reserve'!A:B,2,0),"-") -> Maths - Addition/ Subtraction | D7: =IFERROR(VLOOKUP(B7,'QB Reserve'!A:C,3,0),"-") -> Raju has 10 cookies and Aman has 25. They give their cookies to Aryan. How many cookies does Aryan have now? | E7: =IFERROR(VLOOKUP($B7,'QB Reserve'!$A:$N,E$2,0),"-") -> 35 | F7: =IFERROR(VLOOKUP($B7,'QB Reserve'!$A:$N,F$2,0),"-") -> 30 | G7: =IFERROR(VLOOKUP($B7,'QB Reserve'!$A:$N,G$2,0),"-") -> 0 | H7: =IFERROR(VLOOKUP($B7,'QB Reserve'!$A:$N,H$2,0),"-") -> 0 | I7: =IFERROR(VLOOKUP($B7,'QB Reserve'!$A:$N,I$2,0),"-") -> 0 | J7: =IFERROR(VLOOKUP($B7,'QB Reserve'!$A:$N,J$2,0),"-") -> 0 | K7: =IFERROR(VLOOKUP($B7,'QB Reserve'!$A:$N,K$2,0),"-") -> 0 | L7: =IFERROR(VLOOKUP($B7,'QB Reserve'!$A:$N,L$2,0),"-") -> 0 | ... N7: =IFERROR(VLOOKUP($B7,'QB Reserve'!$A:$N,N$2,0),"-") -> 0 | P7: =IFERROR(VLOOKUP(B7,'QB Reserve'!A:P,16,0),"-") -> Assume variables and add | Q7: =IFERROR(VLOOKUP(B7,'QB Reserve'!A:Q,17,0),"-") -> 2 | R7: =IFERROR(VLOOKUP(B7,'QB Reserve'!A:T,20,0),"-") -> 3 | S7: =+VLOOKUP(B7,'QB Reserve'!A:W,23,0) -> User 3
A8: =+IF(LEN(D8)>5,A7+1,"-") -> 4 | B8: 2 | C8: =IFERROR(VLOOKUP(B8,'QB Reserve'!A:B,2,0),"-") -> Maths - Decimals | D8: =IFERROR(VLOOKUP(B8,'QB Reserve'!A:C,3,0),"-") -> How many decimal points remain when 5.236 is multiplied with 100 | E8: =IFERROR(VLOOKUP($B8,'QB Reserve'!$A:$N,E$2,0),"-") -> 0 | F8: =IFERROR(VLOOKUP($B8,'QB Reserve'!$A:$N,F$2,0),"-") -> 1 | G8: =IFERROR(VLOOKUP($B8,'QB Reserve'!$A:$N,G$2,0),"-") -> 2 | H8: =IFERROR(VLOOKUP($B8,'QB Reserve'!$A:$N,H$2,0),"-") -> 3 | I8: =IFERROR(VLOOKUP($B8,'QB Reserve'!$A:$N,I$2,0),"-") -> 0 | J8: =IFERROR(VLOOKUP($B8,'QB Reserve'!$A:$N,J$2,0),"-") -> 0 | K8: =IFERROR(VLOOKUP($B8,'QB Reserve'!$A:$N,K$2,0),"-") -> 0 | L8: =IFERROR(VLOOKUP($B8,'QB Reserve'!$A:$N,L$2,0),"-") -> 0 | ... N8: =IFERROR(VLOOKUP($B8,'QB Reserve'!$A:$N,N$2,0),"-") -> 0 | P8: =IFERROR(VLOOKUP(B8,'QB Reserve'!A:P,16,0),"-") -> Multiply by 100 and check number of digits after decimal point | Q8: =IFERROR(VLOOKUP(B8,'QB Reserve'!A:Q,17,0),"-") -> 2 | R8: =IFERROR(VLOOKUP(B8,'QB Reserve'!A:T,20,0),"-") -> 1 mins | S8: =+VLOOKUP(B8,'QB Reserve'!A:W,23,0) -> User 2
A9: =+IF(LEN(D9)>5,A8+1,"-") -> 5 | B9: 5 | C9: =IFERROR(VLOOKUP(B9,'QB Reserve'!A:B,2,0),"-") -> Maths - Addition/ Subtraction | D9: =IFERROR(VLOOKUP(B9,'QB Reserve'!A:C,3,0),"-") -> What will be the result if 256 is added to 200? | E9: =IFERROR(VLOOKUP($B9,'QB Reserve'!$A:$N,E$2,0),"-") -> 356 | F9: =IFERROR(VLOOKUP($B9,'QB Reserve'!$A:$N,F$2,0),"-") -> 466 | G9: =IFERROR(VLOOKUP($B9,'QB Reserve'!$A:$N,G$2,0),"-") -> 456 | H9: =IFERROR(VLOOKUP($B9,'QB Reserve'!$A:$N,H$2,0),"-") -> 0 | I9: =IFERROR(VLOOKUP($B9,'QB Reserve'!$A:$N,I$2,0),"-") -> 0 | J9: =IFERROR(VLOOKUP($B9,'QB Reserve'!$A:$N,J$2,0),"-") -> 0 | K9: =IFERROR(VLOOKUP($B9,'QB Reserve'!$A:$N,K$2,0),"-") -> 0 | L9: =IFERROR(VLOOKUP($B9,'QB Reserve'!$A:$N,L$2,0),"-") -> 0 | ... N9: =IFERROR(VLOOKUP($B9,'QB Reserve'!$A:$N,N$2,0),"-") -> 0 | P9: =IFERROR(VLOOKUP(B9,'QB Reserve'!A:P,16,0),"-") -> 0 | Q9: =IFERROR(VLOOKUP(B9,'QB Reserve'!A:Q,17,0),"-") -> 3 | R9: =IFERROR(VLOOKUP(B9,'QB Reserve'!A:T,20,0),"-") -> 1 | S9: =+VLOOKUP(B9,'QB Reserve'!A:W,23,0) -> User 1
A10: =+IF(LEN(D10)>5,A9+1,"-") -> 6 | B10: 8 | C10: =IFERROR(VLOOKUP(B10,'QB Reserve'!A:B,2,0),"-") -> Maths - Time | D10: =IFERROR(VLOOKUP(B10,'QB Reserve'!A:C,3,0),"-") -> Convert 1 hour and 15 minutes into minutes | E10: =IFERROR(VLOOKUP($B10,'QB Reserve'!$A:$N,E$2,0),"-") -> 75 | F10: =IFERROR(VLOOKUP($B10,'QB Reserve'!$A:$N,F$2,0),"-") -> 65 | G10: =IFERROR(VLOOKUP($B10,'QB Reserve'!$A:$N,G$2,0),"-") -> 115 | H10: =IFERROR(VLOOKUP($B10,'QB Reserve'!$A:$N,H$2,0),"-") -> 0 | I10: =IFERROR(VLOOKUP($B10,'QB Reserve'!$A:$N,I$2,0),"-") -> 0 | J10: =IFERROR(VLOOKUP($B10,'QB Reserve'!$A:$N,J$2,0),"-") -> 0 | K10: =IFERROR(VLOOKUP($B10,'QB Reserve'!$A:$N,K$2,0),"-") -> 0 | L10: =IFERROR(VLOOKUP($B10,'QB Reserve'!$A:$N,L$2,0),"-") -> 0 | ... N10: =IFERROR(VLOOKUP($B10,'QB Reserve'!$A:$N,N$2,0),"-") -> 0 | P10: =IFERROR(VLOOKUP(B10,'QB Reserve'!A:P,16,0),"-") -> 1 hour is 60 minutes | Q10: =IFERROR(VLOOKUP(B10,'QB Reserve'!A:Q,17,0),"-") -> 4 | R10: =IFERROR(VLOOKUP(B10,'QB Reserve'!A:T,20,0),"-") -> 6 | S10: =+VLOOKUP(B10,'QB Reserve'!A:W,23,0) -> User 1
A11: =+IF(LEN(D11)>5,A10+1,"-") -> 7 | B11: 9 | C11: =IFERROR(VLOOKUP(B11,'QB Reserve'!A:B,2,0),"-") -> Maths - Time | D11: =IFERROR(VLOOKUP(B11,'QB Reserve'!A:C,3,0),"-") -> How many seconds are in 1 hour? | E11: =IFERROR(VLOOKUP($B11,'QB Reserve'!$A:$N,E$2,0),"-") -> 3000 | F11: =IFERROR(VLOOKUP($B11,'QB Reserve'!$A:$N,F$2,0),"-") -> 3600 | G11: =IFERROR(VLOOKUP($B11,'QB Reserve'!$A:$N,G$2,0),"-") -> 0 | H11: =IFERROR(VLOOKUP($B11,'QB Reserve'!$A:$N,H$2,0),"-") -> 0 | I11: =IFERROR(VLOOKUP($B11,'QB Reserve'!$A:$N,I$2,0),"-") -> 0 | J11: =IFERROR(VLOOKUP($B11,'QB Reserve'!$A:$N,J$2,0),"-") -> 0 | K11: =IFERROR(VLOOKUP($B11,'QB Reserve'!$A:$N,K$2,0),"-") -> 0 | L11: =IFERROR(VLOOKUP($B11,'QB Reserve'!$A:$N,L$2,0),"-") -> 0 | ... N11: =IFERROR(VLOOKUP($B11,'QB Reserve'!$A:$N,N$2,0),"-") -> 0 | P11: =IFERROR(VLOOKUP(B11,'QB Reserve'!A:P,16,0),"-") -> 0 | Q11: =IFERROR(VLOOKUP(B11,'QB Reserve'!A:Q,17,0),"-") -> 2 | R11: =IFERROR(VLOOKUP(B11,'QB Reserve'!A:T,20,0),"-") -> 8 | S11: =+VLOOKUP(B11,'QB Reserve'!A:W,23,0) -> User 3
A12: =+IF(LEN(D12)>5,A11+1,"-") -> - | C12: =IFERROR(VLOOKUP(B12,'QB Reserve'!A:B,2,0),"-") -> - | D12: =IFERROR(VLOOKUP(B12,'QB Reserve'!A:C,3,0),"-") -> - | E12: =IFERROR(VLOOKUP($B12,'QB Reserve'!$A:$N,E$2,0),"-") -> - | F12: =IFERROR(VLOOKUP($B12,'QB Reserve'!$A:$N,F$2,0),"-") -> - | G12: =IFERROR(VLOOKUP($B12,'QB Reserve'!$A:$N,G$2,0),"-") -> - | H12: =IFERROR(VLOOKUP($B12,'QB Reserve'!$A:$N,H$2,0),"-") -> - | I12: =IFERROR(VLOOKUP($B12,'QB Reserve'!$A:$N,I$2,0),"-") -> - | J12: =IFERROR(VLOOKUP($B12,'QB Reserve'!$A:$N,J$2,0),"-") -> - | K12: =IFERROR(VLOOKUP($B12,'QB Reserve'!$A:$N,K$2,0),"-") -> - | L12: =IFERROR(VLOOKUP($B12,'QB Reserve'!$A:$N,L$2,0),"-") -> - | ... N12: =IFERROR(VLOOKUP($B12,'QB Reserve'!$A:$N,N$2,0),"-") -> - | P12: =IFERROR(VLOOKUP(B12,'QB Reserve'!A:P,16,0),"-") -> - | Q12: =IFERROR(VLOOKUP(B12,'QB Reserve'!A:Q,17,0),"-") -> - | R12: =IFERROR(VLOOKUP(B12,'QB Reserve'!A:T,20,0),"-") -> -
A13: =+IF(LEN(D13)>5,A12+1,"-") -> - | C13: =IFERROR(VLOOKUP(B13,'QB Reserve'!A:B,2,0),"-") -> - | D13: =IFERROR(VLOOKUP(B13,'QB Reserve'!A:C,3,0),"-") -> - | E13: =IFERROR(VLOOKUP($B13,'QB Reserve'!$A:$N,E$2,0),"-") -> - | F13: =IFERROR(VLOOKUP($B13,'QB Reserve'!$A:$N,F$2,0),"-") -> - | G13: =IFERROR(VLOOKUP($B13,'QB Reserve'!$A:$N,G$2,0),"-") -> - | H13: =IFERROR(VLOOKUP($B13,'QB Reserve'!$A:$N,H$2,0),"-") -> - | I13: =IFERROR(VLOOKUP($B13,'QB Reserve'!$A:$N,I$2,0),"-") -> - | J13: =IFERROR(VLOOKUP($B13,'QB Reserve'!$A:$N,J$2,0),"-") -> - | K13: =IFERROR(VLOOKUP($B13,'QB Reserve'!$A:$N,K$2,0),"-") -> - | L13: =IFERROR(VLOOKUP($B13,'QB Reserve'!$A:$N,L$2,0),"-") -> - | ... N13: =IFERROR(VLOOKUP($B13,'QB Reserve'!$A:$N,N$2,0),"-") -> - | P13: =IFERROR(VLOOKUP(B13,'QB Reserve'!A:P,16,0),"-") -> - | Q13: =IFERROR(VLOOKUP(B13,'QB Reserve'!A:Q,17,0),"-") -> - | R13: =IFERROR(VLOOKUP(B13,'QB Reserve'!A:T,20,0),"-") -> -
A14: =+IF(LEN(D14)>5,A13+1,"-") -> - | C14: =IFERROR(VLOOKUP(B14,'QB Reserve'!A:B,2,0),"-") -> - | D14: =IFERROR(VLOOKUP(B14,'QB Reserve'!A:C,3,0),"-") -> - | E14: =IFERROR(VLOOKUP($B14,'QB Reserve'!$A:$N,E$2,0),"-") -> - | F14: =IFERROR(VLOOKUP($B14,'QB Reserve'!$A:$N,F$2,0),"-") -> - | G14: =IFERROR(VLOOKUP($B14,'QB Reserve'!$A:$N,G$2,0),"-") -> - | H14: =IFERROR(VLOOKUP($B14,'QB Reserve'!$A:$N,H$2,0),"-") -> - | I14: =IFERROR(VLOOKUP($B14,'QB Reserve'!$A:$N,I$2,0),"-") -> - | J14: =IFERROR(VLOOKUP($B14,'QB Reserve'!$A:$N,J$2,0),"-") -> - | K14: =IFERROR(VLOOKUP($B14,'QB Reserve'!$A:$N,K$2,0),"-") -> - | L14: =IFERROR(VLOOKUP($B14,'QB Reserve'!$A:$N,L$2,0),"-") -> - | ... N14: =IFERROR(VLOOKUP($B14,'QB Reserve'!$A:$N,N$2,0),"-") -> - | P14: =IFERROR(VLOOKUP(B14,'QB Reserve'!A:P,16,0),"-") -> - | Q14: =IFERROR(VLOOKUP(B14,'QB Reserve'!A:Q,17,0),"-") -> - | R14: =IFERROR(VLOOKUP(B14,'QB Reserve'!A:T,20,0),"-") -> -
A15: =+IF(LEN(D15)>5,A14+1,"-") -> - | C15: =IFERROR(VLOOKUP(B15,'QB Reserve'!A:B,2,0),"-") -> - | D15: =IFERROR(VLOOKUP(B15,'QB Reserve'!A:C,3,0),"-") -> - | E15: =IFERROR(VLOOKUP($B15,'QB Reserve'!$A:$N,E$2,0),"-") -> - | F15: =IFERROR(VLOOKUP($B15,'QB Reserve'!$A:$N,F$2,0),"-") -> - | G15: =IFERROR(VLOOKUP($B15,'QB Reserve'!$A:$N,G$2,0),"-") -> - | H15: =IFERROR(VLOOKUP($B15,'QB Reserve'!$A:$N,H$2,0),"-") -> - | I15: =IFERROR(VLOOKUP($B15,'QB Reserve'!$A:$N,I$2,0),"-") -> - | J15: =IFERROR(VLOOKUP($B15,'QB Reserve'!$A:$N,J$2,0),"-") -> - | K15: =IFERROR(VLOOKUP($B15,'QB Reserve'!$A:$N,K$2,0),"-") -> - | L15: =IFERROR(VLOOKUP($B15,'QB Reserve'!$A:$N,L$2,0),"-") -> - | ... N15: =IFERROR(VLOOKUP($B15,'QB Reserve'!$A:$N,N$2,0),"-") -> - | P15: =IFERROR(VLOOKUP(B15,'QB Reserve'!A:P,16,0),"-") -> - | Q15: =IFERROR(VLOOKUP(B15,'QB Reserve'!A:Q,17,0),"-") -> - | R15: =IFERROR(VLOOKUP(B15,'QB Reserve'!A:T,20,0),"-") -> -
A16: =+IF(LEN(D16)>5,A15+1,"-") -> - | C16: =IFERROR(VLOOKUP(B16,'QB Reserve'!A:B,2,0),"-") -> - | D16: =IFERROR(VLOOKUP(B16,'QB Reserve'!A:C,3,0),"-") -> - | E16: =IFERROR(VLOOKUP($B16,'QB Reserve'!$A:$N,E$2,0),"-") -> - | F16: =IFERROR(VLOOKUP($B16,'QB Reserve'!$A:$N,F$2,0),"-") -> - | G16: =IFERROR(VLOOKUP($B16,'QB Reserve'!$A:$N,G$2,0),"-") -> - | H16: =IFERROR(VLOOKUP($B16,'QB Reserve'!$A:$N,H$2,0),"-") -> - | I16: =IFERROR(VLOOKUP($B16,'QB Reserve'!$A:$N,I$2,0),"-") -> - | J16: =IFERROR(VLOOKUP($B16,'QB Reserve'!$A:$N,J$2,0),"-") -> - | K16: =IFERROR(VLOOKUP($B16,'QB Reserve'!$A:$N,K$2,0),"-") -> - | L16: =IFERROR(VLOOKUP($B16,'QB Reserve'!$A:$N,L$2,0),"-") -> - | ... N16: =IFERROR(VLOOKUP($B16,'QB Reserve'!$A:$N,N$2,0),"-") -> - | P16: =IFERROR(VLOOKUP(B16,'QB Reserve'!A:P,16,0),"-") -> - | Q16: =IFERROR(VLOOKUP(B16,'QB Reserve'!A:Q,17,0),"-") -> - | R16: =IFERROR(VLOOKUP(B16,'QB Reserve'!A:T,20,0),"-") -> -
A17: =+IF(LEN(D17)>5,A16+1,"-") -> - | C17: =IFERROR(VLOOKUP(B17,'QB Reserve'!A:B,2,0),"-") -> - | D17: =IFERROR(VLOOKUP(B17,'QB Reserve'!A:C,3,0),"-") -> - | E17: =IFERROR(VLOOKUP($B17,'QB Reserve'!$A:$N,E$2,0),"-") -> - | F17: =IFERROR(VLOOKUP($B17,'QB Reserve'!$A:$N,F$2,0),"-") -> - | G17: =IFERROR(VLOOKUP($B17,'QB Reserve'!$A:$N,G$2,0),"-") -> - | H17: =IFERROR(VLOOKUP($B17,'QB Reserve'!$A:$N,H$2,0),"-") -> - | I17: =IFERROR(VLOOKUP($B17,'QB Reserve'!$A:$N,I$2,0),"-") -> - | J17: =IFERROR(VLOOKUP($B17,'QB Reserve'!$A:$N,J$2,0),"-") -> - | K17: =IFERROR(VLOOKUP($B17,'QB Reserve'!$A:$N,K$2,0),"-") -> - | L17: =IFERROR(VLOOKUP($B17,'QB Reserve'!$A:$N,L$2,0),"-") -> - | ... N17: =IFERROR(VLOOKUP($B17,'QB Reserve'!$A:$N,N$2,0),"-") -> - | P17: =IFERROR(VLOOKUP(B17,'QB Reserve'!A:P,16,0),"-") -> - | Q17: =IFERROR(VLOOKUP(B17,'QB Reserve'!A:Q,17,0),"-") -> - | R17: =IFERROR(VLOOKUP(B17,'QB Reserve'!A:T,20,0),"-") -> -
A18: =+IF(LEN(D18)>5,A17+1,"-") -> - | C18: =IFERROR(VLOOKUP(B18,'QB Reserve'!A:B,2,0),"-") -> - | D18: =IFERROR(VLOOKUP(B18,'QB Reserve'!A:C,3,0),"-") -> - | E18: =IFERROR(VLOOKUP($B18,'QB Reserve'!$A:$N,E$2,0),"-") -> - | F18: =IFERROR(VLOOKUP($B18,'QB Reserve'!$A:$N,F$2,0),"-") -> - | G18: =IFERROR(VLOOKUP($B18,'QB Reserve'!$A:$N,G$2,0),"-") -> - | H18: =IFERROR(VLOOKUP($B18,'QB Reserve'!$A:$N,H$2,0),"-") -> - | I18: =IFERROR(VLOOKUP($B18,'QB Reserve'!$A:$N,I$2,0),"-") -> - | J18: =IFERROR(VLOOKUP($B18,'QB Reserve'!$A:$N,J$2,0),"-") -> - | K18: =IFERROR(VLOOKUP($B18,'QB Reserve'!$A:$N,K$2,0),"-") -> - | L18: =IFERROR(VLOOKUP($B18,'QB Reserve'!$A:$N,L$2,0),"-") -> - | ... N18: =IFERROR(VLOOKUP($B18,'QB Reserve'!$A:$N,N$2,0),"-") -> - | P18: =IFERROR(VLOOKUP(B18,'QB Reserve'!A:P,16,0),"-") -> - | Q18: =IFERROR(VLOOKUP(B18,'QB Reserve'!A:Q,17,0),"-") -> - | R18: =IFERROR(VLOOKUP(B18,'QB Reserve'!A:T,20,0),"-") -> -
A19: =+IF(LEN(D19)>5,A18+1,"-") -> - | C19: =IFERROR(VLOOKUP(B19,'QB Reserve'!A:B,2,0),"-") -> - | D19: =IFERROR(VLOOKUP(B19,'QB Reserve'!A:C,3,0),"-") -> - | E19: =IFERROR(VLOOKUP($B19,'QB Reserve'!$A:$N,E$2,0),"-") -> - | F19: =IFERROR(VLOOKUP($B19,'QB Reserve'!$A:$N,F$2,0),"-") -> - | G19: =IFERROR(VLOOKUP($B19,'QB Reserve'!$A:$N,G$2,0),"-") -> - | H19: =IFERROR(VLOOKUP($B19,'QB Reserve'!$A:$N,H$2,0),"-") -> - | I19: =IFERROR(VLOOKUP($B19,'QB Reserve'!$A:$N,I$2,0),"-") -> - | J19: =IFERROR(VLOOKUP($B19,'QB Reserve'!$A:$N,J$2,0),"-") -> - | K19: =IFERROR(VLOOKUP($B19,'QB Reserve'!$A:$N,K$2,0),"-") -> - | L19: =IFERROR(VLOOKUP($B19,'QB Reserve'!$A:$N,L$2,0),"-") -> - | ... N19: =IFERROR(VLOOKUP($B19,'QB Reserve'!$A:$N,N$2,0),"-") -> - | P19: =IFERROR(VLOOKUP(B19,'QB Reserve'!A:P,16,0),"-") -> - | Q19: =IFERROR(VLOOKUP(B19,'QB Reserve'!A:Q,17,0),"-") -> - | R19: =IFERROR(VLOOKUP(B19,'QB Reserve'!A:T,20,0),"-") -> -
A20: =+IF(LEN(D20)>5,A19+1,"-") -> - | C20: =IFERROR(VLOOKUP(B20,'QB Reserve'!A:B,2,0),"-") -> - | D20: =IFERROR(VLOOKUP(B20,'QB Reserve'!A:C,3,0),"-") -> - | E20: =IFERROR(VLOOKUP($B20,'QB Reserve'!$A:$N,E$2,0),"-") -> - | F20: =IFERROR(VLOOKUP($B20,'QB Reserve'!$A:$N,F$2,0),"-") -> - | G20: =IFERROR(VLOOKUP($B20,'QB Reserve'!$A:$N,G$2,0),"-") -> - | H20: =IFERROR(VLOOKUP($B20,'QB Reserve'!$A:$N,H$2,0),"-") -> - | I20: =IFERROR(VLOOKUP($B20,'QB Reserve'!$A:$N,I$2,0),"-") -> - | J20: =IFERROR(VLOOKUP($B20,'QB Reserve'!$A:$N,J$2,0),"-") -> - | K20: =IFERROR(VLOOKUP($B20,'QB Reserve'!$A:$N,K$2,0),"-") -> - | L20: =IFERROR(VLOOKUP($B20,'QB Reserve'!$A:$N,L$2,0),"-") -> - | ... N20: =IFERROR(VLOOKUP($B20,'QB Reserve'!$A:$N,N$2,0),"-") -> - | P20: =IFERROR(VLOOKUP(B20,'QB Reserve'!A:P,16,0),"-") -> - | Q20: =IFERROR(VLOOKUP(B20,'QB Reserve'!A:Q,17,0),"-") -> - | R20: =IFERROR(VLOOKUP(B20,'QB Reserve'!A:T,20,0),"-") -> -
A21: =+IF(LEN(D21)>5,A20+1,"-") -> - | C21: =IFERROR(VLOOKUP(B21,'QB Reserve'!A:B,2,0),"-") -> - | D21: =IFERROR(VLOOKUP(B21,'QB Reserve'!A:C,3,0),"-") -> - | E21: =IFERROR(VLOOKUP($B21,'QB Reserve'!$A:$N,E$2,0),"-") -> - | F21: =IFERROR(VLOOKUP($B21,'QB Reserve'!$A:$N,F$2,0),"-") -> - | G21: =IFERROR(VLOOKUP($B21,'QB Reserve'!$A:$N,G$2,0),"-") -> - | H21: =IFERROR(VLOOKUP($B21,'QB Reserve'!$A:$N,H$2,0),"-") -> - | I21: =IFERROR(VLOOKUP($B21,'QB Reserve'!$A:$N,I$2,0),"-") -> - | J21: =IFERROR(VLOOKUP($B21,'QB Reserve'!$A:$N,J$2,0),"-") -> - | K21: =IFERROR(VLOOKUP($B21,'QB Reserve'!$A:$N,K$2,0),"-") -> - | L21: =IFERROR(VLOOKUP($B21,'QB Reserve'!$A:$N,L$2,0),"-") -> - | ... N21: =IFERROR(VLOOKUP($B21,'QB Reserve'!$A:$N,N$2,0),"-") -> - | P21: =IFERROR(VLOOKUP(B21,'QB Reserve'!A:P,16,0),"-") -> - | Q21: =IFERROR(VLOOKUP(B21,'QB Reserve'!A:Q,17,0),"-") -> - | R21: =IFERROR(VLOOKUP(B21,'QB Reserve'!A:T,20,0),"-") -> -
A22: =+IF(LEN(D22)>5,A21+1,"-") -> - | C22: =IFERROR(VLOOKUP(B22,'QB Reserve'!A:B,2,0),"-") -> - | D22: =IFERROR(VLOOKUP(B22,'QB Reserve'!A:C,3,0),"-") -> - | E22: =IFERROR(VLOOKUP($B22,'QB Reserve'!$A:$N,E$2,0),"-") -> - | F22: =IFERROR(VLOOKUP($B22,'QB Reserve'!$A:$N,F$2,0),"-") -> - | G22: =IFERROR(VLOOKUP($B22,'QB Reserve'!$A:$N,G$2,0),"-") -> - | H22: =IFERROR(VLOOKUP($B22,'QB Reserve'!$A:$N,H$2,0),"-") -> - | I22: =IFERROR(VLOOKUP($B22,'QB Reserve'!$A:$N,I$2,0),"-") -> - | J22: =IFERROR(VLOOKUP($B22,'QB Reserve'!$A:$N,J$2,0),"-") -> - | K22: =IFERROR(VLOOKUP($B22,'QB Reserve'!$A:$N,K$2,0),"-") -> - | L22: =IFERROR(VLOOKUP($B22,'QB Reserve'!$A:$N,L$2,0),"-") -> - | ... N22: =IFERROR(VLOOKUP($B22,'QB Reserve'!$A:$N,N$2,0),"-") -> - | P22: =IFERROR(VLOOKUP(B22,'QB Reserve'!A:P,16,0),"-") -> - | Q22: =IFERROR(VLOOKUP(B22,'QB Reserve'!A:Q,17,0),"-") -> - | R22: =IFERROR(VLOOKUP(B22,'QB Reserve'!A:T,20,0),"-") -> -
A23: =+IF(LEN(D23)>5,A22+1,"-") -> - | C23: =IFERROR(VLOOKUP(B23,'QB Reserve'!A:B,2,0),"-") -> - | D23: =IFERROR(VLOOKUP(B23,'QB Reserve'!A:C,3,0),"-") -> - | E23: =IFERROR(VLOOKUP($B23,'QB Reserve'!$A:$N,E$2,0),"-") -> - | F23: =IFERROR(VLOOKUP($B23,'QB Reserve'!$A:$N,F$2,0),"-") -> - | G23: =IFERROR(VLOOKUP($B23,'QB Reserve'!$A:$N,G$2,0),"-") -> - | H23: =IFERROR(VLOOKUP($B23,'QB Reserve'!$A:$N,H$2,0),"-") -> - | I23: =IFERROR(VLOOKUP($B23,'QB Reserve'!$A:$N,I$2,0),"-") -> - | J23: =IFERROR(VLOOKUP($B23,'QB Reserve'!$A:$N,J$2,0),"-") -> - | K23: =IFERROR(VLOOKUP($B23,'QB Reserve'!$A:$N,K$2,0),"-") -> - | L23: =IFERROR(VLOOKUP($B23,'QB Reserve'!$A:$N,L$2,0),"-") -> - | ... N23: =IFERROR(VLOOKUP($B23,'QB Reserve'!$A:$N,N$2,0),"-") -> - | P23: =IFERROR(VLOOKUP(B23,'QB Reserve'!A:P,16,0),"-") -> - | Q23: =IFERROR(VLOOKUP(B23,'QB Reserve'!A:Q,17,0),"-") -> - | R23: =IFERROR(VLOOKUP(B23,'QB Reserve'!A:T,20,0),"-") -> -
... A29: =+IF(LEN(D29)>5,A28+1,"-") -> - | C29: =IFERROR(VLOOKUP(B29,'QB Reserve'!A:B,2,0),"-") -> - | D29: =IFERROR(VLOOKUP(B29,'QB Reserve'!A:C,3,0),"-") -> - | E29: =IFERROR(VLOOKUP($B29,'QB Reserve'!$A:$N,E$2,0),"-") -> - | F29: =IFERROR(VLOOKUP($B29,'QB Reserve'!$A:$N,F$2,0),"-") -> - | G29: =IFERROR(VLOOKUP($B29,'QB Reserve'!$A:$N,G$2,0),"-") -> - | H29: =IFERROR(VLOOKUP($B29,'QB Reserve'!$A:$N,H$2,0),"-") -> - | I29: =IFERROR(VLOOKUP($B29,'QB Reserve'!$A:$N,I$2,0),"-") -> - | J29: =IFERROR(VLOOKUP($B29,'QB Reserve'!$A:$N,J$2,0),"-") -> - | K29: =IFERROR(VLOOKUP($B29,'QB Reserve'!$A:$N,K$2,0),"-") -> - | L29: =IFERROR(VLOOKUP($B29,'QB Reserve'!$A:$N,L$2,0),"-") -> - | ... N29: =IFERROR(VLOOKUP($B29,'QB Reserve'!$A:$N,N$2,0),"-") -> - | P29: =IFERROR(VLOOKUP(B29,'QB Reserve'!A:P,16,0),"-") -> - | Q29: =IFERROR(VLOOKUP(B29,'QB Reserve'!A:Q,17,0),"-") -> - | R29: =IFERROR(VLOOKUP(B29,'QB Reserve'!A:T,20,0),"-") -> -

Sheet Subject Assessment (2)
A1: SUBJECT ASSESSMENT: | D1: Mathematics - Level 2 | F1: TOTAL NO. OF QUESTIONS: | H1: =MAX(A:A) -> 6 | J1: TOTAL SCORE WEIGHTAGE: | L1: =SUM(Q:Q) -> 17 | N1: TOTAL TIME AVAILABLE: | P1: =SUM(R:R)+5 -> 29 | S1: User 1 | T1: =+COUNTIF($S$5:$S$32,S1) -> 1
B2: Created By User 3 having User Role - Process Owner | E2: 5 | F2: 6 | G2: 7 | H2: 8 | I2: 9 | J2: 10 | K2: 11 | L2: 12 | M2: 13 | N2: 14 | S2: User 2 | T2: =+COUNTIF($S$5:$S$32,S2) -> 2
A3: Ques No. | B3: Enter QB Reserve No.* | C3: Map Question to Subject - Topic* | D3: Question Description * | E3: Select Expected Response Type - Multiple Choice Selection* (Min 2) | O3: Select Correct Answer* | P3: Question Hint | Q3: Set Score Weightage* | R3: Total Time avaiable | S3: User 3 | T3: =+COUNTIF($S$5:$S$32,S3) -> 3
B4: 1 - 50 | E4: 1* | F4: 2* | G4: 3 | H4: 4 | I4: 5 | J4: 6 | K4: 7 | L4: 8 | M4: 9 | N4: 10
A5: =+IF(LEN(D5)>5,1,"-") -> 1 | B5: 4 | C5: Maths - Airthmetic | D5: =IFERROR(VLOOKUP(B5,'QB Reserve'!A:C,3,0),"-") -> Radius of circle is 5cm. Find area in cm²? | E5: =IFERROR(VLOOKUP($B5,'QB Reserve'!$A:$N,E$2,0),"-") -> 25π | F5: =IFERROR(VLOOKUP($B5,'QB Reserve'!$A:$N,F$2,0),"-") -> 5π | G5: =IFERROR(VLOOKUP($B5,'QB Reserve'!$A:$N,G$2,0),"-") -> 10π | H5: =IFERROR(VLOOKUP($B5,'QB Reserve'!$A:$N,H$2,0),"-") -> 25 | I5: =IFERROR(VLOOKUP($B5,'QB Reserve'!$A:$N,I$2,0),"-") -> 25π | J5: =IFERROR(VLOOKUP($B5,'QB Reserve'!$A:$N,J$2,0),"-") -> 0 | K5: =IFERROR(VLOOKUP($B5,'QB Reserve'!$A:$N,K$2,0),"-") -> 0 | L5: =IFERROR(VLOOKUP($B5,'QB Reserve'!$A:$N,L$2,0),"-") -> 0 | ... N5: =IFERROR(VLOOKUP($B5,'QB Reserve'!$A:$N,N$2,0),"-") -> 0 | P5: =IFERROR(VLOOKUP(B5,'QB Reserve'!A:P,16,0),"-") -> Area=πr² | Q5: =IFERROR(VLOOKUP(B5,'QB Reserve'!A:Q,17,0),"-") -> 2 | R5: =IFERROR(VLOOKUP(B5,'QB Reserve'!A:T,20,0),"-") -> 2 | S5: =+VLOOKUP(B5,'QB Reserve'!A:W,23,0) -> User 3
A6: =+IF(LEN(D6)>5,A5+1,"-") -> 2 | B6: 7 | C6: =IFERROR(VLOOKUP(B6,'QB Reserve'!A:B,2,0),"-") -> Maths - Addition/ Subtraction | D6: =IFERROR(VLOOKUP(B6,'QB Reserve'!A:C,3,0),"-") -> What will be the result if 35 is Subtract from 63? | E6: =IFERROR(VLOOKUP($B6,'QB Reserve'!$A:$N,E$2,0),"-") -> 13 | F6: =IFERROR(VLOOKUP($B6,'QB Reserve'!$A:$N,F$2,0),"-") -> 25 | G6: =IFERROR(VLOOKUP($B6,'QB Reserve'!$A:$N,G$2,0),"-") -> 28 | H6: =IFERROR(VLOOKUP($B6,'QB Reserve'!$A:$N,H$2,0),"-") -> -28 | I6: =IFERROR(VLOOKUP($B6,'QB Reserve'!$A:$N,I$2,0),"-") -> 0 | J6: =IFERROR(VLOOKUP($B6,'QB Reserve'!$A:$N,J$2,0),"-") -> 0 | K6: =IFERROR(VLOOKUP($B6,'QB Reserve'!$A:$N,K$2,0),"-") -> 0 | L6: =IFERROR(VLOOKUP($B6,'QB Reserve'!$A:$N,L$2,0),"-") -> 0 | ... N6: =IFERROR(VLOOKUP($B6,'QB Reserve'!$A:$N,N$2,0),"-") -> 0 | P6: =IFERROR(VLOOKUP(B6,'QB Reserve'!A:P,16,0),"-") -> 0 | Q6: =IFERROR(VLOOKUP(B6,'QB Reserve'!A:Q,17,0),"-") -> 3 | R6: =IFERROR(VLOOKUP(B6,'QB Reserve'!A:T,20,0),"-") -> 5 | S6: =+VLOOKUP(B6,'QB Reserve'!A:W,23,0) -> User 2
A7: =+IF(LEN(D7)>5,A6+1,"-") -> 3 | B7: 13 | C7: =IFERROR(VLOOKUP(B7,'QB Reserve'!A:B,2,0),"-") -> Maths - Numbers | D7: =IFERROR(VLOOKUP(B7,'QB Reserve'!A:C,3,0),"-") -> What is the exponent of 2 in the prime factorization of 24 | E7: =IFERROR(VLOOKUP($B7,'QB Reserve'!$A:$N,E$2,0),"-") -> 3 | F7: =IFERROR(VLOOKUP($B7,'QB Reserve'!$A:$N,F$2,0),"-") -> 2 | G7: =IFERROR(VLOOKUP($B7,'QB Reserve'!$A:$N,G$2,0),"-") -> 4 | H7: =IFERROR(VLOOKUP($B7,'QB Reserve'!$A:$N,H$2,0),"-") -> 1 | I7: =IFERROR(VLOOKUP($B7,'QB Reserve'!$A:$N,I$2,0),"-") -> 2 | J7: =IFERROR(VLOOKUP($B7,'QB Reserve'!$A:$N,J$2,0),"-") -> 0 | K7: =IFERROR(VLOOKUP($B7,'QB Reserve'!$A:$N,K$2,0),"-") -> 0 | L7: =IFERROR(VLOOKUP($B7,'QB Reserve'!$A:$N,L$2,0),"-") -> 0 | ... N7: =IFERROR(VLOOKUP($B7,'QB Reserve'!$A:$N,N$2,0),"-") -> 0 | P7: =IFERROR(VLOOKUP(B7,'QB Reserve'!A:P,16,0),"-") -> 0 | Q7: =IFERROR(VLOOKUP(B7,'QB Reserve'!A:Q,17,0),"-") -> 6 | R7: =IFERROR(VLOOKUP(B7,'QB Reserve'!A:T,20,0),"-") -> 5 | S7: =+VLOOKUP(B7,'QB Reserve'!A:W,23,0) -> User 3
A8: =+IF(LEN(D8)>5,A7+1,"-") -> 4 | B8: 10 | C8: =IFERROR(VLOOKUP(B8,'QB Reserve'!A:B,2,0),"-") -> Maths - Arithmetic | D8: =IFERROR(VLOOKUP(B8,'QB Reserve'!A:C,3,0),"-") -> What will be the result if 125 is Divided by 5? | E8: =IFERROR(VLOOKUP($B8,'QB Reserve'!$A:$N,E$2,0),"-") -> 20 | F8: =IFERROR(VLOOKUP($B8,'QB Reserve'!$A:$N,F$2,0),"-") -> 10 | G8: =IFERROR(VLOOKUP($B8,'QB Reserve'!$A:$N,G$2,0),"-") -> 25 | H8: =IFERROR(VLOOKUP($B8,'QB Reserve'!$A:$N,H$2,0),"-") -> 30 | I8: =IFERROR(VLOOKUP($B8,'QB Reserve'!$A:$N,I$2,0),"-") -> 0 | J8: =IFERROR(VLOOKUP($B8,'QB Reserve'!$A:$N,J$2,0),"-") -> 0 | K8: =IFERROR(VLOOKUP($B8,'QB Reserve'!$A:$N,K$2,0),"-") -> 0 | L8: =IFERROR(VLOOKUP($B8,'QB Reserve'!$A:$N,L$2,0),"-") -> 0 | ... N8: =IFERROR(VLOOKUP($B8,'QB Reserve'!$A:$N,N$2,0),"-") -> 0 | P8: =IFERROR(VLOOKUP(B8,'QB Reserve'!A:P,16,0),"-") -> 0 | Q8: =IFERROR(VLOOKUP(B8,'QB Reserve'!A:Q,17,0),"-") -> 2 | R8: =IFERROR(VLOOKUP(B8,'QB Reserve'!A:T,20,0),"-") -> 7 | S8: =+VLOOKUP(B8,'QB Reserve'!A:W,23,0) -> User 1
A9: =+IF(LEN(D9)>5,A8+1,"-") -> 5 | B9: 11 | C9: =IFERROR(VLOOKUP(B9,'QB Reserve'!A:B,2,0),"-") -> Maths - Arithmetic | D9: =IFERROR(VLOOKUP(B9,'QB Reserve'!A:C,3,0),"-") -> Divide 1000 into 8 parts. What is the size of each group now? | E9: =IFERROR(VLOOKUP($B9,'QB Reserve'!$A:$N,E$2,0),"-") -> 125 | F9: =IFERROR(VLOOKUP($B9,'QB Reserve'!$A:$N,F$2,0),"-") -> 225 | G9: =IFERROR(VLOOKUP($B9,'QB Reserve'!$A:$N,G$2,0),"-") -> 0 | H9: =IFERROR(VLOOKUP($B9,'QB Reserve'!$A:$N,H$2,0),"-") -> 0 | I9: =IFERROR(VLOOKUP($B9,'QB Reserve'!$A:$N,I$2,0),"-") -> 0 | J9: =IFERROR(VLOOKUP($B9,'QB Reserve'!$A:$N,J$2,0),"-") -> 0 | K9: =IFERROR(VLOOKUP($B9,'QB Reserve'!$A:$N,K$2,0),"-") -> 0 | L9: =IFERROR(VLOOKUP($B9,'QB Reserve'!$A:$N,L$2,0),"-") -> 0 | ... N9: =IFERROR(VLOOKUP($B9,'QB Reserve'!$A:$N,N$2,0),"-") -> 0 | P9: =IFERROR(VLOOKUP(B9,'QB Reserve'!A:P,16,0),"-") -> 0 | Q9: =IFERROR(VLOOKUP(B9,'QB Reserve'!A:Q,17,0),"-") -> 3 | R9: =IFERROR(VLOOKUP(B9,'QB Reserve'!A:T,20,0),"-") -> 2 | S9: =+VLOOKUP(B9,'QB Reserve'!A:W,23,0) -> User 3
A10: =+IF(LEN(D10)>5,A9+1,"-") -> 6 | B10: 12 | C10: =IFERROR(VLOOKUP(B10,'QB Reserve'!A:B,2,0),"-") -> Maths - Numbers | D10: =IFERROR(VLOOKUP(B10,'QB Reserve'!A:C,3,0),"-") -> LCM of 2 numbers is 25. HCF of the two numbers is 3. What is their product? | E10: =IFERROR(VLOOKUP($B10,'QB Reserve'!$A:$N,E$2,0),"-") -> 70 | F10: =IFERROR(VLOOKUP($B10,'QB Reserve'!$A:$N,F$2,0),"-") -> 25 | G10: =IFERROR(VLOOKUP($B10,'QB Reserve'!$A:$N,G$2,0),"-") -> 50 | H10: =IFERROR(VLOOKUP($B10,'QB Reserve'!$A:$N,H$2,0),"-") -> 75 | I10: =IFERROR(VLOOKUP($B10,'QB Reserve'!$A:$N,I$2,0),"-") -> 0 | J10: =IFERROR(VLOOKUP($B10,'QB Reserve'!$A:$N,J$2,0),"-") -> 0 | K10: =IFERROR(VLOOKUP($B10,'QB Reserve'!$A:$N,K$2,0),"-") -> 0 | L10: =IFERROR(VLOOKUP($B10,'QB Reserve'!$A:$N,L$2,0),"-") -> 0 | ... N10: =IFERROR(VLOOKUP($B10,'QB Reserve'!$A:$N,N$2,0),"-") -> 0 | P10: =IFERROR(VLOOKUP(B10,'QB Reserve'!A:P,16,0),"-") -> Product of two numbers is equal to product of their LCM and HCF. | Q10: =IFERROR(VLOOKUP(B10,'QB Reserve'!A:Q,17,0),"-") -> 1 | R10: =IFERROR(VLOOKUP(B10,'QB Reserve'!A:T,20,0),"-") -> 3 | S10: =+VLOOKUP(B10,'QB Reserve'!A:W,23,0) -> User 2
A11: =+IF(LEN(D11)>5,A10+1,"-") -> - | C11: =IFERROR(VLOOKUP(B11,'QB Reserve'!A:B,2,0),"-") -> - | D11: =IFERROR(VLOOKUP(B11,'QB Reserve'!A:C,3,0),"-") -> - | E11: =IFERROR(VLOOKUP($B11,'QB Reserve'!$A:$N,E$2,0),"-") -> - | F11: =IFERROR(VLOOKUP($B11,'QB Reserve'!$A:$N,F$2,0),"-") -> - | G11: =IFERROR(VLOOKUP($B11,'QB Reserve'!$A:$N,G$2,0),"-") -> - | H11: =IFERROR(VLOOKUP($B11,'QB Reserve'!$A:$N,H$2,0),"-") -> - | I11: =IFERROR(VLOOKUP($B11,'QB Reserve'!$A:$N,I$2,0),"-") -> - | J11: =IFERROR(VLOOKUP($B11,'QB Reserve'!$A:$N,J$2,0),"-") -> - | K11: =IFERROR(VLOOKUP($B11,'QB Reserve'!$A:$N,K$2,0),"-") -> - | L11: =IFERROR(VLOOKUP($B11,'QB Reserve'!$A:$N,L$2,0),"-") -> - | ... N11: =IFERROR(VLOOKUP($B11,'QB Reserve'!$A:$N,N$2,0),"-") -> - | P11: =IFERROR(VLOOKUP(B11,'QB Reserve'!A:P,16,0),"-") -> - | Q11: =IFERROR(VLOOKUP(B11,'QB Reserve'!A:Q,17,0),"-") -> - | R11: =IFERROR(VLOOKUP(B11,'QB Reserve'!A:T,20,0),"-") -> -
A12: =+IF(LEN(D12)>5,A11+1,"-") -> - | C12: =IFERROR(VLOOKUP(B12,'QB Reserve'!A:B,2,0),"-") -> - | D12: =IFERROR(VLOOKUP(B12,'QB Reserve'!A:C,3,0),"-") -> - | E12: =IFERROR(VLOOKUP($B12,'QB Reserve'!$A:$N,E$2,0),"-") -> - | F12: =IFERROR(VLOOKUP($B12,'QB Reserve'!$A:$N,F$2,0),"-") -> - | G12: =IFERROR(VLOOKUP($B12,'QB Reserve'!$A:$N,G$2,0),"-") -> - | H12: =IFERROR(VLOOKUP($B12,'QB Reserve'!$A:$N,H$2,0),"-") -> - | I12: =IFERROR(VLOOKUP($B12,'QB Reserve'!$A:$N,I$2,0),"-") -> - | J12: =IFERROR(VLOOKUP($B12,'QB Reserve'!$A:$N,J$2,0),"-") -> - | K12: =IFERROR(VLOOKUP($B12,'QB Reserve'!$A:$N,K$2,0),"-") -> - | L12: =IFERROR(VLOOKUP($B12,'QB Reserve'!$A:$N,L$2,0),"-") -> - | ... N12: =IFERROR(VLOOKUP($B12,'QB Reserve'!$A:$N,N$2,0),"-") -> - | P12: =IFERROR(VLOOKUP(B12,'QB Reserve'!A:P,16,0),"-") -> - | Q12: =IFERROR(VLOOKUP(B12,'QB Reserve'!A:Q,17,0),"-") -> - | R12: =IFERROR(VLOOKUP(B12,'QB Reserve'!A:T,20,0),"-") -> -
A13: =+IF(LEN(D13)>5,A12+1,"-") -> - | C13: =IFERROR(VLOOKUP(B13,'QB Reserve'!A:B,2,0),"-") -> - | D13: =IFERROR(VLOOKUP(B13,'QB Reserve'!A:C,3,0),"-") -> - | E13: =IFERROR(VLOOKUP($B13,'QB Reserve'!$A:$N,E$2,0),"-") -> - | F13: =IFERROR(VLOOKUP($B13,'QB Reserve'!$A:$N,F$2,0),"-") -> - | G13: =IFERROR(VLOOKUP($B13,'QB Reserve'!$A:$N,G$2,0),"-") -> - | H13: =IFERROR(VLOOKUP($B13,'QB Reserve'!$A:$N,H$2,0),"-") -> - | I13: =IFERROR(VLOOKUP($B13,'QB Reserve'!$A:$N,I$2,0),"-") -> - | J13: =IFERROR(VLOOKUP($B13,'QB Reserve'!$A:$N,J$2,0),"-") -> - | K13: =IFERROR(VLOOKUP($B13,'QB Reserve'!$A:$N,K$2,0),"-") -> - | L13: =IFERROR(VLOOKUP($B13,'QB Reserve'!$A:$N,L$2,0),"-") -> - | ... N13: =IFERROR(VLOOKUP($B13,'QB Reserve'!$A:$N,N$2,0),"-") -> - | P13: =IFERROR(VLOOKUP(B13,'QB Reserve'!A:P,16,0),"-") -> - | Q13: =IFERROR(VLOOKUP(B13,'QB Reserve'!A:Q,17,0),"-") -> - | R13: =IFERROR(VLOOKUP(B13,'QB Reserve'!A:T,20,0),"-") -> -
A14: =+IF(LEN(D14)>5,A13+1,"-") -> - | C14: =IFERROR(VLOOKUP(B14,'QB Reserve'!A:B,2,0),"-") -> - | D14: =IFERROR(VLOOKUP(B14,'QB Reserve'!A:C,3,0),"-") -> - | E14: =IFERROR(VLOOKUP($B14,'QB Reserve'!$A:$N,E$2,0),"-") -> - | F14: =IFERROR(VLOOKUP($B14,'QB Reserve'!$A:$N,F$2,0),"-") -> - | G14: =IFERROR(VLOOKUP($B14,'QB Reserve'!$A:$N,G$2,0),"-") -> - | H14: =IFERROR(VLOOKUP($B14,'QB Reserve'!$A:$N,H$2,0),"-") -> - | I14: =IFERROR(VLOOKUP($B14,'QB Reserve'!$A:$N,I$2,0),"-") -> - | J14: =IFERROR(VLOOKUP($B14,'QB Reserve'!$A:$N,J$2,0),"-") -> - | K14: =IFERROR(VLOOKUP($B14,'QB Reserve'!$A:$N,K$2,0),"-") -> - | L14: =IFERROR(VLOOKUP($B14,'QB Reserve'!$A:$N,L$2,0),"-") -> - | ... N14: =IFERROR(VLOOKUP($B14,'QB Reserve'!$A:$N,N$2,0),"-") -> - | P14: =IFERROR(VLOOKUP(B14,'QB Reserve'!A:P,16,0),"-") -> - | Q14: =IFERROR(VLOOKUP(B14,'QB Reserve'!A:Q,17,0),"-") -> - | R14: =IFERROR(VLOOKUP(B14,'QB Reserve'!A:T,20,0),"-") -> -
